Workbook

Sheet support table
A1: Site / Project Name | B1: [NAMA_PROYEK]
A2: Region | B2: [REGION]
A3: Cluster / Subfeeder Name | B3: [NAMA_LOKASI]
A4: Cluster / Subfeeder ID | B4: [ID_LOKASI]
A5: Address | B5: [ALAMAT]
A6: OLT Name | B6: [NAMA_OLT]
A7: FDT ID (Link From) | B7: [ID_FDT_FROM]
A8: FAT ID (Link To) | B8: [ID_FAT_TO]
A9: Vendor Company | B9: [NAMA_PT_VENDOR]
A10: Vendor Rep. Name | B10: [REP_VENDOR]
A11: Vendor Rep. Title | B11: [JABATAN_VENDOR]
A12: Customer Company | B12: [NAMA_PT_CUSTOMER]
... A16: PO Number | B16: [NO_PO]

Sheet ATP CW Cover
A19: ACCEPTANCE TEST PROCEDURE
A20: For
A21: ='support table'!$B$1 -> [NAMA_PROYEK]
A27: ='support table'!$B$12 -> [NAMA_PT_CUSTOMER]
D30: Cluster Name : | F30: ='support table'!$B$3 -> [NAMA_LOKASI]
A32: ="Document Prepared by " & 'support table'!$B$9 -> Document Prepared by [NAMA_PT_VENDOR]
A34: ="Vendor Representation : " & 'support table'!$B$10 -> Vendor Representation : [REP_VENDOR]
A36: ="EMR Representation : " & 'support table'!$B$13 -> EMR Representation : [REP_CUSTOMER]
E38: LOGO VENDOR
A46: ='support table'!$B$9 -> [NAMA_PT_VENDOR]
A48: 2026

Sheet MASTER_FAT
A1: Acceptance Test Procedure
A2: Checklist for Fiber Access Terminal (FAT)
B4: Region : | C4: ='support table'!$B$2 -> [REGION] | E4: Cluster : | F4: ='support table'!$B$3 -> [NAMA_LOKASI]
B5: Link From : | C5: ='support table'!$B$7 -> [ID_FDT_FROM] | E5: To : | F5: ='support table'!$B$8 -> [ID_FAT_TO] | G5: [INPUT_FAT_NAME]
B6: Address : | C6: ='support table'!$B$5 -> [ALAMAT] | E6: Address : | F6: ='support table'!$B$5 -> [ALAMAT]
A8: No. | B8: Item | C8: Requirements | G8: Comment
A9: 1 | B9: Position | C9: Check the position of FAT is installed according to the Design plan | G9: □passed □fail □N/A
C10: Check the stability of FAT and or pedestal fixed on pole/pedestal/wall as per the Design plan | G10: □passed □fail □N/A
C11: Check the pedestal foundation according to the standard design plan | G11: □passed □fail □N/A
A12: 2 | B12: Condition | C12: Ensure the Pedestal and or FAT body is not damage | G12: □passed □fail □N/A
C13: Ensure the FAT adapters are not damage | G13: □passed □fail □N/A
C14: Ensure the FAT pigtails not damage | G14: □passed □fail □N/A
C15: Ensure the FAT adapters & connectors are using SC/APC | G15: □passed □fail □N/A
C16: Ensure the FAT and or pedestal can be open and locked properly | G16: □passed □fail □N/A
A17: 3 | B17: Connection | C17: Ensure the connectors are plugged properly | G17: □passed □fail □N/A
C18: Ensure no pigtail pinched or bending | G18: □passed □fail □N/A
A19: 4 | B19: Label FAT | C19: Check the FAT label and numbering according MR numbering plan | G19: □passed □fail □N/A
C20: Check the cable label and pigtail label | G20: □passed □fail □N/A
A21: ="Comments: " & 'support table'!$B$7 -> Comments: [ID_FDT_FROM]
A22: Signatures:
A23: Responsible Vendor | F23: Responsible Customer
A24: ="Name: " & 'support table'!$B$10 -> Name: [REP_VENDOR] | F24: ="Name: " & 'support table'!$B$13 -> Name: [REP_CUSTOMER]
A25: ID: | F25: ID:
A26: Signature: | F26: Signature
A27: Date: | F27: Date:

Sheet FDT
A1: Acceptance Test Procedure
A2: Checklist for Fiber Distribution Terminal (FDT)
B4: Region : | C4: ='support table'!$B$2 -> [REGION] | F4: Cluster : | G4: ='support table'!$B$3 -> [NAMA_LOKASI]
B5: Link From : | C5: ='support table'!$B$6 -> [NAMA_OLT] | F5: To : | G5: ='support table'!$B$7 -> [ID_FDT_FROM]
B6: Address : | C6: ='support table'!$B$5 -> [ALAMAT] | F6: Address : | G6: ='support table'!$B$5 -> [ALAMAT]
A8: No. | B8: Item | C8: Requirements | H8: Comment
A9: 1 | B9: Position | C9: Check the position of FDT is installed according to the Design plan | H9: □passed □fail □N/A
C10: Check the stability of FDT fixed on the concrete foundation as per Design plan | H10: □passed □fail □N/A
C11: Check the FDT foundation according to the standard design plan | H11: □passed □fail □N/A
A12: 2 | B12: Condition | C12: Ensure the FDT body is not damage | H12: □passed □fail □N/A
C13: Ensure the FDT adapters are not damage | H13: □passed □fail □N/A
C14: Ensure the FDT pigtails not damage | H14: □passed □fail □N/A
C15: Ensure the Splitters installed properly | H15: □passed □fail □N/A
C16: Ensure the FDT splitters, adapters & connectors are using SC/APC | H16: □passed □fail □N/A
C17: Ensure the FDT door can be open and locked properly | H17: □passed □fail □N/A
A18: 3 | B18: Connection | C18: Ensure the connectors are plugged properly | H18: □passed □fail □N/A
C19: Ensure no pigtail pinched or bending | H19: □passed □fail □N/A
C20: Ensure cable route are installed neat & properly | H20: □passed □fail □N/A
A21: 4 | B21: Label FDT | C21: Check the FDT label and numbering according MR numbering plan | H21: □passed □fail □N/A
C22: Check the cable label and pigtail label | H22: □passed □fail □N/A
A23: ="Comments: " & 'support table'!$B$7 -> Comments: [ID_FDT_FROM]
A24: Signatures:
A25: Responsible Vendor | G25: Responsible Customer
A26: ="Name: " & 'support table'!$B$10 -> Name: [REP_VENDOR] | G26: ="Name: " & 'support table'!$B$13 -> Name: [REP_CUSTOMER]
A27: ID: | G27: ID:
A28: Signature: | G28: Signature
A29: Date: | G29: Date:

Sheet MASTER_POLE
A1: Acceptance Test Procedure
A2: Check List for Pole Erection with Accessories (Visual Checking)
B4: Region : | D4: ='support table'!$B$2 -> [REGION] | H4: Cluster/Route : | I4: ='support table'!$B$3 -> [NAMA_LOKASI]
B5: Link From : | D5: ='support table'!$B$6 -> [NAMA_OLT] | H5: To : | I5: ='support table'!$B$7 -> [ID_FDT_FROM]
B6: Address : | D6: ='support table'!$B$5 -> [ALAMAT] | H6: Address : | I6: ='support table'!$B$5 -> [ALAMAT]
A8: Inspection Item
A9: Pole to Pole Span | D9: Height of Pole installed | F9: Pole Depth Solution | H9: Pole Labelling | I9: Pole Accessories | J9: Installation Area Clean | K9: ATP Result
A10: DESCRIPTION => | D10: Pole height (7Mtr/9Mtr) and hole depth comply with standard(1.4m/1.8m), differentiation veticality pole note more than 2 Degree | F10: If hole depth can't reach to the standard requirement | H10: Pole have label pole ID & MQM name labeling | I10: Pole Accessories like - Hanger, Clamps & Etc should follow the Specs. | J10: Pole Foundation and near by area should be neat and clean | K10: Pole Wise ATP Output result
F11: Move to another proposed location | G11: Cut pole to keep same clearance with other pole
A12: [INPUT_POLE_DESC] | D12: [INPUT_POLE_SIZE] | K12: □pass □fail □Need Repair
A32: ="Comments: " & 'support table'!$B$7 -> Comments: [ID_FDT_FROM]
A34: Responsible Vendor | J34: Responsible Customer
A35: ="Name: " & 'support table'!$B$10 -> Name: [REP_VENDOR] | J35: ="Name: " & 'support table'!$B$13 -> Name: [REP_CUSTOMER]
A36: ID: | J36: ID:
A37: Name: | J37: Name:
A40: Name: | J40: Name:
A41: Date: | J41: Date:

Sheet Trenching
A1: Acceptance Test Procedure
A2: Checklist for Civil work- Trench & HDPE laying
B4: Region : | C4: ='support table'!$B$2 -> [REGION] | F4: Cluster : | G4: ='support table'!$B$3 -> [NAMA_LOKASI]
B5: Link From : | C5: ='support table'!$B$6 -> [NAMA_OLT] | F5: To : | G5: ='support table'!$B$7 -> [ID_FDT_FROM]
B6: Address : | C6: ='support table'!$B$5 -> [ALAMAT] | F6: Address : | G6: ='support table'!$B$5 -> [ALAMAT]
A8: No. | B8: Item | C8: Requirements | H8: Comment
A9: 1 | B9: Trenching | C9: The depth of the trench complies the standard | H9: □passed □fail □N/A
A10: 2 | B10: HDPE duct laying | C10: Ensure the duct is not damaged and ends are always covered | H10: □passed □fail □N/A
C11: no damage during placement | H11: □passed □fail □N/A
C12: Correct method of duct coupling | H12: □passed □fail □N/A
A13: 3 | B13: Backfilling | C13: Backfilling & Compaction with same soft soil excavated from the trench | H13: □passed □fail □N/A
A14: 4 | B14: Warning tape | C14: Installation of the warning tape comply standard | H14: □passed □fail □N/A
C15: the logo on the tape is clear | H15: □passed □fail □N/A
A16: 6 | B16: Reinstatement | C16: Asphalt road reinstatement comply with the standard | H16: □passed □fail □N/A
C17: Reinstatement of pavement comply with standard | H17: □passed □fail □N/A
C18: Concrete reinstatement done comply with sandard | H18: □passed □fail □N/A
C19: Reinstatement of grass comply with standard | H19: □passed □fail □N/A
A20: ="Comments: " & 'support table'!$B$7 -> Comments: [ID_FDT_FROM]
A21: Signatures:
A22: Responsible Vendor | G22: Responsible Customer
A23: ="Name: " & 'support table'!$B$10 -> Name: [REP_VENDOR] | G23: ="Name: " & 'support table'!$B$13 -> Name: [REP_CUSTOMER]
A24: ID: | G24: ID:
A25: Signature: | G25: Signature
A26: Date: | G26: Date:

Sheet Road and Railway
A1: Acceptance Test Procedure
A2: Checklist for Road and Railway Crossing
B4: Region : | C4: ='support table'!$B$2 -> [REGION] | E4: Cluster : | F4: ='support table'!$B$3 -> [NAMA_LOKASI]
B5: Link From : | C5: ='support table'!$B$6 -> [NAMA_OLT] | E5: To : | F5: ='support table'!$B$7 -> [ID_FDT_FROM]
B6: Address : | C6: ='support table'!$B$5 -> [ALAMAT] | E6: Address : | F6: ='support table'!$B$5 -> [ALAMAT]
A8: No. | B8: Item | C8: Requirements | G8: Comment
A9: 1 | B9: Railway Boring | C9: Base on local department standard, the boring depth is 1.5~2m from surface | G9: □passed □fail □N/A
C10: Laying HDPE 40/34mm | G10: □passed □fail □N/A
C11: Pit backfilled and Reinstatement | G11: □passed □fail □N/A
A12: 2 | B12: Road Boring | C12: The boring depth is 1.5~2m from surface | G12: □passed □fail □N/A
C13: Lay HDPE 40/34mm | G13: □passed □fail □N/A
C14: Pit backfilled and Reinstatement | G14: □passed □fail □N/A
A15: ="Comments: " & 'support table'!$B$7 -> Comments: [ID_FDT_FROM]
A16: Signatures:
A17: Responsible Vendor | F17: Responsible Customer
A18: ="Name: " & 'support table'!$B$10 -> Name: [REP_VENDOR] | F18: ="Name: " & 'support table'!$B$13 -> Name: [REP_CUSTOMER]
A19: ID: | F19: ID:
A20: Signature: | F20: Signature
A21: Date: | F21: Date:

Sheet Bridges Crossing
A1: Acceptance Test Procedure
A2: Check List for Bridges Crossing
B4: Region : | C4: ='support table'!$B$2 -> [REGION] | E4: Cluster : | F4: ='support table'!$B$3 -> [NAMA_LOKASI]
B5: Link From : | C5: ='support table'!$B$6 -> [NAMA_OLT] | E5: To : | F5: ='support table'!$B$7 -> [ID_FDT_FROM]
B6: Address : | C6: ='support table'!$B$5 -> [ALAMAT] | E6: Address : | F6: ='support table'!$B$5 -> [ALAMAT]
A8: Inspection Item | D8: Criteria | G8: Comment
A9: Self Support ( SS ) | D9: Specified size | G9: □passed □fail □N/A
D10: Firmly | G10: □passed □fail □N/A
D11: Fixed / connected | G11: □passed □fail □N/A
A12: Attachment (ATB) | D12: Specified size | G12: □passed □fail □N/A
D13: Firmly | G13: □passed □fail □N/A
D14: Fixed / connected | G14: □passed □fail □N/A
A15: Single Pole Suspension | D15: Specified size | G15: □passed □fail □N/A
D16: Firmly | G16: □passed □fail □N/A
D17: Fixed / connected | G17: □passed □fail □N/A
A18: Double Pole Suspension | D18: Specified size | G18: □passed □fail □N/A
D19: Firmly | G19: □passed □fail □N/A
D20: Fixed / connected | G20: □passed □fail □N/A
A21: Structure | D21: Conform to drawing | G21: □passed □fail □N/A
A22: Concrete encasement | D22: No cracks | G22: □passed □fail □N/A
A23: Fixing Hardware | D23: Sufficient | G23: □passed □fail □N/A
A24: Cable Tag | D24: Installed as spec | G24: □passed □fail □N/A
A25: Levelling of foundation | D25: Level | G25: □passed □fail □N/A
A26: Reinstatement | D26: Performed | G26: □passed □fail □N/A
A27: ="Comments: " & 'support table'!$B$7 -> Comments: [ID_FDT_FROM]
A31: Signatures:
A32: Responsible Subcontractor | D32: Responsible Vendor | F32: Responsible Customer
A33: Name: | D33: ="Name: " & 'support table'!$B$10 -> Name: [REP_VENDOR] | F33: Name: | G33: ='support table'!$B$13 -> [REP_CUSTOMER]
A34: ID: | D34: ID: | F34: ID:
A35: Signature: | D35: Signature: | F35: Signature
A36: Date: | D36: Date: | F36: Date:

Sheet Precast Handhole
A1: Acceptance Test Procedure
A2: Check List for Precast Handhole/Precast Handhole Pit (Visual Checking)
B4: Region : | C4: ='support table'!$B$2 -> [REGION] | E4: Cluster : | F4: ='support table'!$B$3 -> [NAMA_LOKASI]
B5: Link From : | C5: ='support table'!$B$6 -> [NAMA_OLT] | E5: To : | F5: ='support table'!$B$7 -> [ID_FDT_FROM]
B6: Address : | C6: ='support table'!$B$5 -> [ALAMAT] | E6: Address : | F6: ='support table'!$B$5 -> [ALAMAT]
B7: HH Number : | E7: HH GPS :
B10: Size Measurement
B11: Inner : | C11: Outer:
A12: L
A13: W
A14: D
A16: Note : All measurement in cm
A17: Inspection Item | D17: Criteria | G17: Comment
A18: Placement | D18: Base and Design and actual condition | G18: □passed □fail □N/A
A19: Dimensions | D19: According Spec. | G19: □passed □fail □N/A
A20: HH Foundation | D20: Smooth | G20: □passed □fail □N/A
D21: Frame | G21: □passed □fail □N/A
D22: No Crack | G22: □passed □fail □N/A
A23: HH Wall/Roof | D23: Smooth | G23: □passed □fail □N/A
D24: Frame Bar | G24: □passed □fail □N/A
D25: No Crack | G25: □passed □fail □N/A
A26: Reinstatement (Surface Type) | D26: Performed | G26: □passed □fail □N/A
A27: Name Plate | D27: Provided | G27: □passed □fail □N/A
A28: HH Cover (HH -2 covers,HH Pit 1 cover) | D28: Levelling | G28: □passed □fail □N/A
D29: Frame | G29: □passed □fail □N/A
D30: Handle | G30: □passed □fail □N/A
D31: Identity (MyRepublic) | G31: □passed □fail □N/A
A32: HH & Handhole Pit Accessories | D32: Cable Bracket | G32: □passed □fail □N/A
A33: Label HH & Cable | D33: Cable Bracket,label Handhole ID, Drainase hole etc. | G33: □passed □fail □N/A
A34: ="Comments: " & 'support table'!$B$7 -> Comments: [ID_FDT_FROM]
A38: Signatures:
A39: Responsible Vendor | F39: Responsible Customer
A40: ="Name: " & 'support table'!$B$10 -> Name: [REP_VENDOR] | F40: ="Name: " & 'support table'!$B$13 -> Name: [REP_CUSTOMER]
A41: ID: | F41: ID:
A42: Signature: | F42: Signature
A43: Date: | F43: Date:

Sheet Handhole
A1: Acceptance Test Procedure
A2: Check List for Handhole/Handhole Pit (Visual Checking)
B4: Region : | C4: ='support table'!$B$2 -> [REGION] | E4: Cluster : | F4: ='support table'!$B$3 -> [NAMA_LOKASI]
B5: Link From : | C5: ='support table'!$B$6 -> [NAMA_OLT] | E5: To : | F5: ='support table'!$B$7 -> [ID_FDT_FROM]
B6: Address : | C6: ='support table'!$B$5 -> [ALAMAT] | E6: Address : | F6: ='support table'!$B$5 -> [ALAMAT]
B7: HH Number : | E7: HH GPS :
B10: Size Measurement
B11: Inner : | C11: Outer:
A12: L
A13: W
A14: D
A16: Note : All measurement in cm
A17: Inspection Item | D17: Criteria | G17: Comment
A18: Placement | D18: Base and Design and actual condition | G18: □passed □fail □N/A
A19: Dimensions | D19: According Spec. | G19: □passed □fail □N/A
A20: HH Foundation | D20: Smooth | G20: □passed □fail □N/A
D21: Frame | G21: □passed □fail □N/A
D22: No Crack | G22: □passed □fail □N/A
A23: HH Wall/Roof | D23: Smooth | G23: □passed □fail □N/A
D24: Frame Bar | G24: □passed □fail □N/A
D25: No Crack | G25: □passed □fail □N/A
A26: Reinstatement (Surface Type) | D26: Performed | G26: □passed □fail □N/A
A27: Name Plate | D27: Provided | G27: □passed □fail □N/A
A28: HH Cover (HH -2 covers,HH Pit 1 cover) | D28: Levelling | G28: □passed □fail □N/A
D29: Frame | G29: □passed □fail □N/A
D30: Handle | G30: □passed □fail □N/A
D31: Identity (MyRepublic) | G31: □passed □fail □N/A
A32: HH & Handhole Pit Accessories | D32: Cable Bracket | G32: □passed □fail □N/A
A33: Label HH & Cable | D33: Cable Bracket,label Handhole ID, Drainase hole etc. | G33: □passed □fail □N/A
A34: ="Comments: " & 'support table'!$B$7 -> Comments: [ID_FDT_FROM]
A38: Signatures:
A39: Responsible Vendor | F39: Responsible Customer
A40: ="Name: " & 'support table'!$B$10 -> Name: [REP_VENDOR] | F40: ="Name: " & 'support table'!$B$13 -> Name: [REP_CUSTOMER]
A41: ID: | F41: ID:
A42: Signature: | F42: Signature
A43: Date: | F43: Date:

Sheet Boring Rojok Manual
A1: Acceptance Test Procedure
A2: Checklist for Boring Rojok Manual (BRM)
B4: Region : | C4: ='support table'!$B$2 -> [REGION] | E4: Cluster : | F4: ='support table'!$B$3 -> [NAMA_LOKASI]
B5: Link From : | C5: ='support table'!$B$6 -> [NAMA_OLT] | E5: To : | F5: ='support table'!$B$7 -> [ID_FDT_FROM]
B6: Address : | C6: ='support table'!$B$5 -> [ALAMAT] | E6: Address : | F6: ='support table'!$B$5 -> [ALAMAT]
A8: No. | B8: Item | C8: Requirements | G8: Comment
A9: 1 | B9: Boring Rojok Manual | C9: The boring depth is 1.5 m from surface in feeder part | G9: □passed □fail □N/A
C10: The boring depth is 0.3 m from surface in [TIPE] part | G10: □passed □fail □N/A
C11: Lay HDPE 40/34mm | G11: □passed □fail □N/A
C12: Backfilled pit | G12: □passed □fail □N/A
C13: Surface Reinstatement | G13: □passed □fail □N/A
C14: Site Cleaness | G14: □passed □fail □N/A
A15: Boring Rojok manaual is similar meaning with Manual Boring
A16: Signatures:
A17: Responsible Vendor | F17: Responsible Customer
A18: ="Name: " & 'support table'!$B$10 -> Name: [REP_VENDOR] | F18: ="Name:" & 'support table'!$B$13 -> Name:[REP_CUSTOMER]
A19: ID: | F19: ID:
A20: Signature: | F20: Signature
A21: Date: | F21: Date:

Sheet Building cable access
A1: Acceptance Test Procedure
A2: Check List for Building Cable Access
B4: Region : | C4: ='support table'!$B$2 -> [REGION] | E4: Cluster : | F4: ='support table'!$B$3 -> [NAMA_LOKASI]
B5: Link From : | C5: ='support table'!$B$6 -> [NAMA_OLT] | E5: To : | F5: ='support table'!$B$7 -> [ID_FDT_FROM]
B6: Address : | C6: ='support table'!$B$5 -> [ALAMAT] | E6: Address : | F6: ='support table'!$B$5 -> [ALAMAT]
A9: Inspection Item | D9: Criteria | G9: Comment
A10: Sealing at Entry Pipe | D10: Conform | G10: □passed □fail □N/A
A11: Cable Installation | D11: Conform | G11: □passed □fail □N/A
A12: Wall Fixing at Entry Pipe | D12: Conform | G12: □passed □fail □N/A
A13: Cable Labelling | D13: Provided & Correct | G13: □passed □fail □N/A
A14: Spare Cable Installation | D14: Conform | G14: □passed □fail □N/A
A15: ="Comments: " & 'support table'!$B$7 -> Comments: [ID_FDT_FROM]
A18: Signatures:
A19: Responsible Vendor | F19: Responsible Customer
A20: ="Name: " & 'support table'!$B$10 -> Name: [REP_VENDOR] | F20: ="Name: " & 'support table'!$B$13 -> Name: [REP_CUSTOMER]
A21: ID: | F21: ID:
A22: Name: | F22: Signature
A23: Date: | F23: Date:

Sheet Cable installation
A1: Acceptance Test Procedure
A2: Checklist for Cable Installation in HH,HH Pit and OTB (Visual Inspection)
B4: Region : | C4: ='support table'!$B$2 -> [REGION] | E4: Cluster : | F4: ='support table'!$B$3 -> [NAMA_LOKASI]
B5: Link From : | C5: ='support table'!$B$6 -> [NAMA_OLT] | E5: To : | F5: ='support table'!$B$7 -> [ID_FDT_FROM]
B6: Address : | C6: ='support table'!$B$5 -> [ALAMAT] | E6: Address : | F6: ='support table'!$B$5 -> [ALAMAT]
A8: No. | B8: Item | C8: Requirements | G8: Comment
A9: 1 | B9: Handhole | C9: Cable Arrangement and coil in 10m slack on bracket | G9: □passed □fail □N/A
C10: Joint closure and excess cable on the bracket properly | G10: □passed □fail □N/A
C11: Cleaness of handhole after cable pulled | G11: □passed □fail □N/A
A12: 2 | B12: HH Pit | C12: Cable Arrangement and coil in 10m side slack | G12: □passed □fail □N/A
C13: Cable Place on the bracket properly | G13: □passed □fail □N/A
C14: Cleaness of handhole after cable pulled | G14: □passed □fail □N/A
A15: 3 | B15: OTB | C15: Cable enter to the OTB properly | G15: □passed □fail □N/A
C16: Cable protected by corrugated HDPE (exposed) | G16: □passed □fail □N/A
C17: Cable arrangement enter to the cabinet properly | G17: □passed □fail □N/A
C18: Label OTB and Port (PTB harus di label dan keterangan susunan port) | G18: □passed □fail □N/A
A19: 4 | B19: Aerial Cable | C19: The cable ground clearance conform to required height | G19: □passed □fail □N/A
C20: The slack cable is coiled in the coiling holder at >20 times the cable diameter (15-20 meter) | G20: □passed □fail □N/A
C21: The cable is properly tensioned /clamped / wrapped | G21: □passed □fail □N/A
C22: Cable is properly secured at the pole | G22: □passed □fail □N/A
C23: Bending radius 20 times of cable diameter at turning point | G23: □passed □fail □N/A
C24: Cable damage | G24: □passed □fail □N/A
C25: Cable labelling | G25: □passed □fail □N/A
A26: ="Comments: " & 'support table'!$B$7 -> Comments: [ID_FDT_FROM]
A27: Signatures:
A28: Responsible Vendor | F28: Responsible Customer
A29: ="Name: " & 'support table'!$B$10 -> Name: [REP_VENDOR] | F29: ="Name: " & 'support table'!$B$13 -> Name: [REP_CUSTOMER]
A30: ID: | F30: ID:
A31: Signatures: | F31: Signature
A32: Date: | F32: Date:

Sheet BA RECTIFIKASI CW ATP
A1: BERITA ACARA RECTIFIKASI PUNCH LIST
A4: Pada hari ini, tanggal , bulan , tahun , kami yang bertanda tangan di bawah ini:
A7: Nama | C7: =": " & 'support table'!$B$10 -> : [REP_VENDOR]
A8: Perusahaan | C8: =": " & 'support table'!$B$9 -> : [NAMA_PT_VENDOR]
A11: Nama | C11: =": " & 'support table'!$B$13 -> : [REP_CUSTOMER]
A12: Perusahaan | C12: =": " & 'support table'!$B$12 -> : [NAMA_PT_CUSTOMER]
A14: Telah melaksanakan pengecekan ulang untuk hasil rektifikasi punch list Civil Work seperti dibawah ini dengan hasil
A15: BAIK dan DITERIMA.
A18: Cluster Name | B18: : | C18: ='support table'!$B$3 -> [NAMA_LOKASI]
A20: Cluster ID | B20: : | C20: ='support table'!$B$4 -> [ID_LOKASI]
A22: ATP Date | B22: :
A26: FDT | B26: No | C26: Defect Item | E26: Defect Description | I26: Punch Point Type | K26: Result | L26: Date of Clearence
B27: 1
B48: ='support table'!$B$9 -> [NAMA_PT_VENDOR] | H48: ='support table'!$B$12 -> [NAMA_PT_CUSTOMER]
B56: Nama | C56: =": " & 'support table'!$B$10 -> : [REP_VENDOR] | J56: Nama | K56: =": " & 'support table'!$B$13 -> : [REP_CUSTOMER]

Sheet CW Punchpoint defect list
A1: RECORD OF PUNCH LIST CW ATP
A2: Project Name | B2: : | C2: ='support table'!$B$1 -> [NAMA_PROYEK]
A3: Cluster Name | B3: : | C3: ='support table'!$B$3 -> [NAMA_LOKASI]
A4: Cluster ID | B4: : | C4: ='support table'!$B$4 -> [ID_LOKASI]
A5: ATP Date | B5: :
A7: No | B7: Defect Item | D7: Target Date | F7: Repaired Date | G7: Sign (customer)
A30: Signatures:
A32: Responsible Vendor | D32: Responsible Customer | F32: Responsible Vendor | G32: Responsible Customer
A33: ="Name: " & 'support table'!$B$10 -> Name: [REP_VENDOR] | D33: ="Name: " & 'support table'!$B$13 -> Name: [REP_CUSTOMER] | F33: ="Name: " & 'support table'!$B$10 -> Name: [REP_VENDOR] | G33: ="Name: " & 'support table'!$B$13 -> Name: [REP_CUSTOMER]
A34: ID: | D34: ID: | F34: ID: | G34: ID:
A35: Signature: | D35: Signature: | F35: Signature: | G35: Signature:
A36: Date: | D36: Date: | F36: Date: | G36: Date:

Sheet Cover CW OPM
A1: Acceptance Test Procedure
A2: OPM Test Report
C15: Cluster Name : | D15: ='support table'!$B$3 -> [NAMA_LOKASI]
A17: Signatures:
B18: Responsible Vendor | F18: Responsible Customer
B20: ="Name: " & 'support table'!$B$10 -> Name: [REP_VENDOR] | F20: ="Name: " & 'support table'!$B$13 -> Name: [REP_CUSTOMER]
B21: ID: | F21: ID:
B22: Signature: | F22: Signature
B23: Date: | F23: Date:

Sheet MASTER_OPM
A1: Acceptance Test Procedure
A2: End to End Power Meter Measurement Test
A3: Region: | B3: ='support table'!$B$2 -> [REGION] | H3: Cluster : | I3: ='support table'!$B$4 -> [ID_LOKASI] | M3: Light Source mode : | N3: OLT □Laser Source □
A4: OLT Name: | B4: ='support table'!$B$6 -> [NAMA_OLT] | H4: ODF Number : | M4: FDT Number : | N4: ='support table'!$B$7 -> [ID_FDT_FROM]
A5: Address: | B5: ='support table'!$B$5 -> [ALAMAT] | H5: OPM Calibration Deviation : | M5: Power Meter model/SN :
A7: Feeder Core | B7: Wave Length (1490nm) | C7: Spliter SN | E7: Test (dBm) | I7: Feeder Core | J7: Wave Length (1490nm) | K7: Spliter SN | L7: Test (dBm)
E8: Port | F8: Before Splitter | G8: Port | H8: After Splitter | L8: Port | M8: Before Splitter | N8: Port | O8: After Splitter
A9: 1 | B9: [SPL_ID] | C9: [SPL_SN] | E9: 1 | F9: [OPM_BEFORE] | G9: 1 | H9: [OPM_AFTER] | I9: 3 | J9: [SPL_ID] | K9: [SPL_SN] | L9: 1 | M9: [OPM_BEFORE] | N9: 1 | O9: [OPM_AFTER]
G10: 2 | H10: [OPM_AFTER] | N10: 2 | O10: [OPM_AFTER]
G11: 3 | H11: [OPM_AFTER] | N11: 3 | O11: [OPM_AFTER]
G12: 4 | H12: [OPM_AFTER] | N12: 4 | O12: [OPM_AFTER]
G13: 5 | H13: [OPM_AFTER] | N13: 5 | O13: [OPM_AFTER]
G14: 6 | H14: [OPM_AFTER] | N14: 6 | O14: [OPM_AFTER]
G15: 7 | H15: [OPM_AFTER] | N15: 7 | O15: [OPM_AFTER]
G16: 8 | H16: [OPM_AFTER] | N16: 8 | O16: [OPM_AFTER]
A17: 2 | B17: [SPL_ID] | C17: [SPL_SN] | E17: 1 | F17: [OPM_BEFORE] | G17: 1 | H17: [OPM_AFTER] | I17: 4 | J17: [SPL_ID] | K17: [SPL_SN] | L17: 1 | M17: [OPM_BEFORE] | N17: 1 | O17: [OPM_AFTER]
G18: 2 | H18: [OPM_AFTER] | N18: 2 | O18: [OPM_AFTER]
G19: 3 | H19: [OPM_AFTER] | N19: 3 | O19: [OPM_AFTER]
G20: 4 | H20: [OPM_AFTER] | N20: 4 | O20: [OPM_AFTER]
G21: 5 | H21: [OPM_AFTER] | N21: 5 | O21: [OPM_AFTER]
G22: 6 | H22: [OPM_AFTER] | N22: 6 | O22: [OPM_AFTER]
G23: 7 | H23: [OPM_AFTER] | N23: 7 | O23: [OPM_AFTER]
G24: 8 | H24: [OPM_AFTER] | N24: 8 | O24: [OPM_AFTER]
A30: Signatures:
A31: Responsible Vendor Responsible Customer | L31: Responsible Customer
A32: ="Name: " & 'support table'!$B$10 -> Name: [REP_VENDOR] | L32: ="Name: " & 'support table'!$B$13 -> Name: [REP_CUSTOMER]
A33: Signature: | L33: Signature:
A35: Date: | L35: Date:

Sheet MASTER_OPM_DISTRIBUTION
A1: Acceptance Test Procedure
A2: End to End Power Meter Measurement Test
A4: Region : | B4: ='support table'!$B$2 -> [REGION] | H4: Cluster : | I4: ='support table'!$B$3 -> [NAMA_LOKASI] | O4: Light Source mode : | P4: OLT □ Laser Source □
A5: OLT Name : | B5: ='support table'!$B$6 -> [NAMA_OLT] | H5: ODF Number : | O5: FDT Number : | P5: ='support table'!$B$7 -> [ID_FDT_FROM]
A6: Address : | B6: ='support table'!$B$5 -> [ALAMAT] | H6: OPM Calibration Deviation : | O6: Power Meter model/SN :
A8: FAT Number | B8: Fiber Nymber | C8: Wave Length (nm ) | D8: Test (dBm) | E8: FAT Number | F8: Fiber Number | G8: Wave Length (nm ) | H8: Test (dBm) | I8: FAT Number | J8: Fiber Number | K8: Wave Length (nm ) | L8: Test (dBm) | M8: FAT Number | N8: Fiber Number | O8: Wave Length (nm ) | P8: Test (dBm) | Q8: FAT Number | R8: Fiber Number | S8: Wave Length (nm ) | T8: Test (dBm)
A10: [INPUT_FAT_NAME] | B10: 1 | C10: 1490 | D10: [INPUT_OPM] | E10: [INPUT_FAT_NAME] | F10: 1 | G10: 1490 | H10: [INPUT_OPM] | I10: [INPUT_FAT_NAME] | J10: 1 | K10: 1490 | L10: [INPUT_OPM] | M10: [INPUT_FAT_NAME] | N10: 1 | O10: 1490 | P10: [INPUT_OPM] | Q10: [INPUT_FAT_NAME] | R10: 1 | S10: 1490 | T10: [INPUT_OPM]
B11: 2 | C11: 1490 | D11: [INPUT_OPM] | F11: 2 | G11: 1490 | H11: [INPUT_OPM] | J11: 2 | K11: 1490 | L11: [INPUT_OPM] | N11: 2 | O11: 1490 | P11: [INPUT_OPM] | R11: 2 | S11: 1490 | T11: [INPUT_OPM]
B12: 3 | C12: 1490 | D12: [INPUT_OPM] | F12: 3 | G12: 1490 | H12: [INPUT_OPM] | J12: 3 | K12: 1490 | L12: [INPUT_OPM] | N12: 3 | O12: 1490 | P12: [INPUT_OPM] | R12: 3 | S12: 1490 | T12: [INPUT_OPM]
B13: 4 | C13: 1490 | D13: [INPUT_OPM] | F13: 4 | G13: 1490 | H13: [INPUT_OPM] | J13: 4 | K13: 1490 | L13: [INPUT_OPM] | N13: 4 | O13: 1490 | P13: [INPUT_OPM] | R13: 4 | S13: 1490 | T13: [INPUT_OPM]
B14: 5 | C14: 1490 | D14: [INPUT_OPM] | F14: 5 | G14: 1490 | H14: [INPUT_OPM] | J14: 5 | K14: 1490 | L14: [INPUT_OPM] | N14: 5 | O14: 1490 | P14: [INPUT_OPM] | R14: 5 | S14: 1490 | T14: [INPUT_OPM]
B15: 6 | C15: 1490 | D15: [INPUT_OPM] | F15: 6 | G15: 1490 | H15: [INPUT_OPM] | J15: 6 | K15: 1490 | L15: [INPUT_OPM] | N15: 6 | O15: 1490 | P15: [INPUT_OPM] | R15: 6 | S15: 1490 | T15: [INPUT_OPM]
B16: 7 | C16: 1490 | D16: [INPUT_OPM] | F16: 7 | G16: 1490 | H16: [INPUT_OPM] | J16: 7 | K16: 1490 | L16: [INPUT_OPM] | N16: 7 | O16: 1490 | P16: [INPUT_OPM] | R16: 7 | S16: 1490 | T16: [INPUT_OPM]
B17: 8 | C17: 1490 | D17: [INPUT_OPM] | F17: 8 | G17: 1490 | H17: [INPUT_OPM] | J17: 8 | K17: 1490 | L17: [INPUT_OPM] | N17: 8 | O17: 1490 | P17: [INPUT_OPM] | R17: 8 | S17: 1490 | T17: [INPUT_OPM]
B18: 9 | C18: 1490 | F18: 9 | G18: 1490 | J18: 9 | K18: 1490 | N18: 9 | O18: 1490 | R18: 9 | S18: 1490
B19: 10 | C19: 1490 | F19: 10 | G19: 1490 | J19: 10 | K19: 1490 | N19: 10 | O19: 1490 | R19: 10 | S19: 1490
B20: 11 | C20: 1490 | F20: 11 | G20: 1490 | J20: 11 | K20: 1490 | N20: 11 | O20: 1490 | R20: 11 | S20: 1490
B21: 12 | C21: 1490 | F21: 12 | G21: 1490 | J21: 12 | K21: 1490 | N21: 12 | O21: 1490 | R21: 12 | S21: 1490
B22: 13 | C22: 1490 | F22: 13 | G22: 1490 | J22: 13 | K22: 1490 | N22: 13 | O22: 1490 | R22: 13 | S22: 1490
B23: 14 | C23: 1490 | F23: 14 | G23: 1490 | J23: 14 | K23: 1490 | N23: 14 | O23: 1490 | R23: 14 | S23: 1490
B24: 15 | C24: 1490 | F24: 15 | G24: 1490 | J24: 15 | K24: 1490 | N24: 15 | O24: 1490 | R24: 15 | S24: 1490
B25: 16 | C25: 1490 | F25: 16 | G25: 1490 | J25: 16 | K25: 1490 | N25: 16 | O25: 1490 | R25: 16 | S25: 1490
A26: [INPUT_FAT_NAME] | B26: 1 | C26: 1490 | D26: [INPUT_OPM] | E26: [INPUT_FAT_NAME] | F26: 1 | G26: 1490 | H26: [INPUT_OPM] | I26: [INPUT_FAT_NAME] | J26: 1 | K26: 1490 | L26: [INPUT_OPM] | M26: [INPUT_FAT_NAME] | N26: 1 | O26: 1490 | P26: [INPUT_OPM] | Q26: [INPUT_FAT_NAME] | R26: 1 | S26: 1490 | T26: [INPUT_OPM]
B27: 2 | C27: 1490 | D27: [INPUT_OPM] | F27: 2 | G27: 1490 | H27: [INPUT_OPM] | J27: 2 | K27: 1490 | L27: [INPUT_OPM] | N27: 2 | O27: 1490 | P27: [INPUT_OPM] | R27: 2 | S27: 1490 | T27: [INPUT_OPM]
B28: 3 | C28: 1490 | D28: [INPUT_OPM] | F28: 3 | G28: 1490 | H28: [INPUT_OPM] | J28: 3 | K28: 1490 | L28: [INPUT_OPM] | N28: 3 | O28: 1490 | P28: [INPUT_OPM] | R28: 3 | S28: 1490 | T28: [INPUT_OPM]
B29: 4 | C29: 1490 | D29: [INPUT_OPM] | F29: 4 | G29: 1490 | H29: [INPUT_OPM] | J29: 4 | K29: 1490 | L29: [INPUT_OPM] | N29: 4 | O29: 1490 | P29: [INPUT_OPM] | R29: 4 | S29: 1490 | T29: [INPUT_OPM]
B30: 5 | C30: 1490 | D30: [INPUT_OPM] | F30: 5 | G30: 1490 | H30: [INPUT_OPM] | J30: 5 | K30: 1490 | L30: [INPUT_OPM] | N30: 5 | O30: 1490 | P30: [INPUT_OPM] | R30: 5 | S30: 1490 | T30: [INPUT_OPM]
B31: 6 | C31: 1490 | D31: [INPUT_OPM] | F31: 6 | G31: 1490 | H31: [INPUT_OPM] | J31: 6 | K31: 1490 | L31: [INPUT_OPM] | N31: 6 | O31: 1490 | P31: [INPUT_OPM] | R31: 6 | S31: 1490 | T31: [INPUT_OPM]
B32: 7 | C32: 1490 | D32: [INPUT_OPM] | F32: 7 | G32: 1490 | H32: [INPUT_OPM] | J32: 7 | K32: 1490 | L32: [INPUT_OPM] | N32: 7 | O32: 1490 | P32: [INPUT_OPM] | R32: 7 | S32: 1490 | T32: [INPUT_OPM]
B33: 8 | C33: 1490 | D33: [INPUT_OPM] | F33: 8 | G33: 1490 | H33: [INPUT_OPM] | J33: 8 | K33: 1490 | L33: [INPUT_OPM] | N33: 8 | O33: 1490 | P33: [INPUT_OPM] | R33: 8 | S33: 1490 | T33: [INPUT_OPM]
B34: 9 | C34: 1490 | F34: 9 | G34: 1490 | J34: 9 | K34: 1490 | N34: 9 | O34: 1490 | R34: 9 | S34: 1490
B35: 10 | C35: 1490 | F35: 10 | G35: 1490 | J35: 10 | K35: 1490 | N35: 10 | O35: 1490 | R35: 10 | S35: 1490
B36: 11 | C36: 1490 | F36: 11 | G36: 1490 | J36: 11 | K36: 1490 | N36: 11 | O36: 1490 | R36: 11 | S36: 1490
B37: 12 | C37: 1490 | F37: 12 | G37: 1490 | J37: 12 | K37: 1490 | N37: 12 | O37: 1490 | R37: 12 | S37: 1490
B38: 13 | C38: 1490 | F38: 13 | G38: 1490 | J38: 13 | K38: 1490 | N38: 13 | O38: 1490 | R38: 13 | S38: 1490
B39: 14 | C39: 1490 | F39: 14 | G39: 1490 | J39: 14 | K39: 1490 | N39: 14 | O39: 1490 | R39: 14 | S39: 1490
B40: 15 | C40: 1490 | F40: 15 | G40: 1490 | J40: 15 | K40: 1490 | N40: 15 | O40: 1490 | R40: 15 | S40: 1490
B41: 16 | C41: 1490 | F41: 16 | G41: 1490 | J41: 16 | K41: 1490 | N41: 16 | O41: 1490 | R41: 16 | S41: 1490
A48: Signatures:
A49: Responsible Vendor | P49: Responsible Customer
...

Sheet MASTER OTDR Sumary (FDT-FAT)
A1: Splice Loss Measurement (Result from OTDR) FDT to FAT
A5: Project Name | D5: : | E5: ='support table'!$B$1 -> [NAMA_PROYEK] | M5: Date Test : | N5: ='support table'!$B$15 -> [TANGGAL_TEST]
A6: Region | D6: : | E6: ='support table'!$B$2 -> [REGION] | M6: OLT : | N6: ='support table'!$B$6 -> [NAMA_OLT]
A7: Cluster Name | D7: : | E7: ='support table'!$B$3 -> [NAMA_LOKASI] | M7: Line No : | N7: ='support table'!$B$7 -> [ID_FDT_FROM]
A10: Tube | C10: Core | E10: FAT NO. | F10: Distance (Km) | G10: (FDT - FAT) Loss (dB) | I10: Tube | K10: Core | M10: FAT NO. | N10: Distance (Km) | O10: (FDT - FAT) Loss (dB)
A11: No | B11: Color | C11: No | D11: Color | G11: 1310 nm | H11: 1550 nm | I11: No | J11: Color | K11: No | L11: Color | O11: 1310 nm | P11: 1550 nm
A12: 1 | B12: BLUE | C12: 1 | D12: Blue | E12: [INPUT_FAT_NAME] | F12: [DISTANCE] | G12: [1310] | I12: 5 | J12: SLATE | K12: 1 | L12: Blue | M12: [INPUT_FAT_NAME] | N12: [DISTANCE] | O12: [1310]
C13: 2 | D13: Orange | H13: [1550] | K13: 2 | L13: Orange | P13: [1550]
C14: 3 | D14: Green | E14: [INPUT_FAT_NAME] | F14: [DISTANCE] | G14: [1310] | K14: 3 | L14: Green | M14: [INPUT_FAT_NAME] | N14: [DISTANCE] | O14: [1310]
C15: 4 | D15: Brown | H15: [1550] | K15: 4 | L15: Brown | P15: [1550]
C16: 5 | D16: Slate | E16: [INPUT_FAT_NAME] | F16: [DISTANCE] | G16: [1310] | K16: 5 | L16: Slate | M16: [INPUT_FAT_NAME] | N16: [DISTANCE] | O16: [1310]
C17: 6 | D17: White | H17: [1550] | K17: 6 | L17: White | P17: [1550]
C18: 7 | D18: Red | E18: [INPUT_FAT_NAME] | F18: [DISTANCE] | G18: [1310] | K18: 7 | L18: Red | M18: [INPUT_FAT_NAME] | N18: [DISTANCE] | O18: [1310]
C19: 8 | D19: Black | H19: [1550] | K19: 8 | L19: Black | P19: [1550]
C20: 9 | D20: Yellow | E20: [INPUT_FAT_NAME] | F20: [DISTANCE] | G20: [1310] | K20: 9 | L20: Yellow | M20: [INPUT_FAT_NAME] | N20: [DISTANCE] | O20: [1310]
C21: 10 | D21: Purple | H21: [1550] | K21: 10 | L21: Purple | P21: [1550]
C22: 11 | D22: Pink | K22: 11 | L22: Pink
C23: 12 | D23: Aqua | K23: 12 | L23: Aqua
A24: 2 | B24: ORANGE | C24: 1 | D24: Blue | E24: [INPUT_FAT_NAME] | G24: [1310] | I24: 6 | J24: WHITE | K24: 1 | L24: Blue | M24: [INPUT_FAT_NAME] | O24: [1310]
C25: 2 | D25: Orange | H25: [1550] | K25: 2 | L25: Orange | P25: [1550]
C26: 3 | D26: Green | E26: [INPUT_FAT_NAME] | G26: [1310] | K26: 3 | L26: Green | M26: [INPUT_FAT_NAME] | O26: [1310]
C27: 4 | D27: Brown | H27: [1550] | K27: 4 | L27: Brown | P27: [1550]
C28: 5 | D28: Slate | E28: [INPUT_FAT_NAME] | G28: [1310] | K28: 5 | L28: Slate | M28: [INPUT_FAT_NAME] | O28: [1310]
C29: 6 | D29: White | H29: [1550] | K29: 6 | L29: White | P29: [1550]
C30: 7 | D30: Red | E30: [INPUT_FAT_NAME] | G30: [1310] | K30: 7 | L30: Red | M30: [INPUT_FAT_NAME] | O30: [1310]
C31: 8 | D31: Black | H31: [1550] | K31: 8 | L31: Black | P31: [1550]
C32: 9 | D32: Yellow | E32: [INPUT_FAT_NAME] | G32: [1310] | K32: 9 | L32: Yellow | M32: [INPUT_FAT_NAME] | O32: [1310]
C33: 10 | D33: Purple | H33: [1550] | K33: 10 | L33: Purple | P33: [1550]
C34: 11 | D34: Pink | K34: 11 | L34: Pink
C35: 12 | D35: Aqua | K35: 12 | L35: Aqua
A36: 3 | B36: GREEN | C36: 1 | D36: Blue | E36: [INPUT_FAT_NAME] | G36: [1310] | I36: 7 | J36: RED | K36: 1 | L36: Blue | M36: [INPUT_FAT_NAME] | O36: [1310]
C37: 2 | D37: Orange | H37: [1550] | K37: 2 | L37: Orange | P37: [1550]
C38: 3 | D38: Green | E38: [INPUT_FAT_NAME] | G38: [1310] | K38: 3 | L38: Green | M38: [INPUT_FAT_NAME] | O38: [1310]
C39: 4 | D39: Brown | H39: [1550] | K39: 4 | L39: Brown | P39: [1550]
C40: 5 | D40: Slate | E40: [INPUT_FAT_NAME] | G40: [1310] | K40: 5 | L40: Slate | M40: [INPUT_FAT_NAME] | O40: [1310]
C41: 6 | D41: White | H41: [1550] | K41: 6 | L41: White | P41: [1550]
C42: 7 | D42: Red | E42: [INPUT_FAT_NAME] | G42: [1310] | K42: 7 | L42: Red | M42: [INPUT_FAT_NAME] | O42: [1310]
C43: 8 | D43: Black | H43: [1550] | K43: 8 | L43: Black | P43: [1550]
C44: 9 | D44: Yellow | E44: [INPUT_FAT_NAME] | G44: [1310] | K44: 9 | L44: Yellow | M44: [INPUT_FAT_NAME] | O44: [1310]
C45: 10 | D45: Purple | H45: [1550] | K45: 10 | L45: Purple | P45: [1550]
...

Sheet OTDR Summary 
A1: Splice Loss Measurement (Result from OTDR) OLT TO FDT Wavelength [WAVE_LENGHT]
A6: Project Name | C6: : | D6: ='support table'!$B$1 -> [NAMA_PROYEK] | I6: Date Test : | J6: =_xlfn.SINGLE('[1]OTDR Summary 1310 '!J6) -> :
A7: Region | C7: : | D7: ='support table'!$B$7 -> [ID_FDT_FROM] | I7: LINK : | J7: ='support table'!$B$5 -> [ALAMAT]
A8: From (A) | C8: : | D8: ='support table'!$B$6 -> [NAMA_OLT] | I8: Line No : | J8: ='support table'!$B$7 -> [ID_FDT_FROM]
A10: CABLE | E10: JOINT SPLICE
A11: IOR : | B11: 1310nm : 0.3373 | E11: JOINT NO : | H11: JOINT NO : | K11: JOINT NO :
B12: 1550nm : 0.3374 | E12: Distance (Km) | H12: Distance (Km) | K12: Distance (Km)
A13: Splice Threshold : 0.01db | E13: SPAN | F13: TO OTDR | G13: TO OTDR | H13: SPAN | I13: TO OTDR | J13: TO OTDR | K13: SPAN | L13: TO OTDR | M13: TO OTDR
F14: (A - B) | G14: (B - A) | I14: (A - B) | J14: (B - A) | L14: (A - B) | M14: (B - A)
A15: TUBE | C15: CORE
E16: SPLICE LOSS | H16: SPLICE LOSS | K16: SPLICE LOSS
A17: NO | B17: COLOR | C17: NO | D17: COLOR | E17: Direction | F17: Distance (Km) | G17: OTDR (dB) | H17: Direction | I17: Distance (Km) | J17: OTDR (dB) | K17: Direction | L17: Distance (Km) | M17: OTDR (dB)
A18: 1 | B18: BLUE | C18: 1 | D18: Blue | E18: A - B | F18: [DISTANCE_SF] | G18: [OTDR_SF] | H18: A - B | K18: A - B
E19: B - A | H19: B - A | K19: B - A
C20: 2 | D20: Orange | E20: A - B | F20: [DISTANCE_SF] | G20: [OTDR_SF] | H20: A - B | K20: A - B
E21: B - A | H21: B - A | K21: B - A
C22: 3 | D22: Green | E22: A - B | F22: [DISTANCE_SF] | G22: [OTDR_SF] | H22: A - B | K22: A - B
E23: B - A | H23: B - A | K23: B - A
C24: 4 | D24: Brown | E24: A - B | F24: [DISTANCE_SF] | G24: [OTDR_SF] | H24: A - B | K24: A - B
E25: B - A | H25: B - A | K25: B - A
C26: 5 | D26: Slate | E26: A - B | F26: [DISTANCE_SF] | G26: [OTDR_SF] | H26: A - B | K26: A - B
E27: B - A | H27: B - A | K27: B - A
C28: 6 | D28: White | E28: A - B | F28: [DISTANCE_SF] | G28: [OTDR_SF] | H28: A - B | K28: A - B
E29: B - A | H29: B - A | K29: B - A
C30: 7 | D30: Red | E30: A - B | F30: [DISTANCE_SF] | G30: [OTDR_SF] | H30: A - B | K30: A - B
E31: B - A | H31: B - A | K31: B - A
C32: 8 | D32: Black | E32: A - B | F32: [DISTANCE_SF] | G32: [OTDR_SF] | H32: A - B | K32: A - B
E33: B - A | H33: B - A | K33: B - A
C34: 9 | D34: Yellow | E34: A - B | F34: [DISTANCE_SF] | G34: [OTDR_SF] | H34: A - B | K34: A - B
E35: B - A | H35: B - A | K35: B - A
C36: 10 | D36: Purple | E36: A - B | F36: [DISTANCE_SF] | G36: [OTDR_SF] | H36: A - B | K36: A - B
E37: B - A | H37: B - A | K37: B - A
C38: 11 | D38: Pink | E38: A - B | H38: A - B | K38: A - B
E39: B - A | H39: B - A | K39: B - A
C40: 12 | D40: Aqua | E40: A - B | H40: A - B | K40: A - B
E41: B - A | H41: B - A | K41: B - A
A42: 2 | B42: ORANGE | C42: 13 | D42: Blue | E42: A - B | F42: [DISTANCE_SF] | G42: [OTDR_SF] | H42: A - B | K42: A - B
E43: B - A | H43: B - A | K43: B - A
C44: 14 | D44: Orange | E44: A - B | F44: [DISTANCE_SF] | G44: [OTDR_SF] | H44: A - B | K44: A - B
E45: B - A | H45: B - A | K45: B - A
...

Sheet OPM Punchpoint defect list
A1: RECORD OF PUNCH LIST OPM ATP
A2: Project Name | B2: : | C2: ='support table'!$B$1 -> [NAMA_PROYEK]
A3: Cluster Name | B3: : | C3: ='support table'!$B$3 -> [NAMA_LOKASI]
A4: Cluster ID | B4: : | C4: ='support table'!$B$4 -> [ID_LOKASI]
A5: ATP Date | B5: :
A7: No | B7: Defect Item | D7: Target Date | F7: Repaired Date | G7: Sign (customer)
A30: Signatures:
A32: Responsible Vendor | D32: Responsible Customer | F32: Responsible Vendor | G32: Responsible Customer
A33: ="Name: " & 'support table'!$B$10 -> Name: [REP_VENDOR] | D33: ="Name: " & 'support table'!$B$13 -> Name: [REP_CUSTOMER] | F33: ="Name: " & 'support table'!$B$10 -> Name: [REP_VENDOR] | G33: ="Name: " & 'support table'!$B$13 -> Name: [REP_CUSTOMER]
A34: ID: | D34: ID: | F34: ID: | G34: ID:
A35: Signature: | D35: Signature: | F35: Signature: | G35: Signature:
A36: Date: | D36: Date: | F36: Date: | G36: Date:

Sheet BA RECTIFIKASI OPM
A1: BERITA ACARA RECTIFIKASI PUNCH LIST
A4: Pada hari ini, tanggal , bulan , tahun , kami yang bertanda tangan di bawah ini:
A7: Nama | C7: =": " & 'support table'!$B$10 -> : [REP_VENDOR]
A8: Perusahaan | C8: =": " & 'support table'!$B$9 -> : [NAMA_PT_VENDOR]
A11: Nama | C11: =": " & 'support table'!$B$13 -> : [REP_CUSTOMER]
A12: Perusahaan | C12: =": " & 'support table'!$B$12 -> : [NAMA_PT_CUSTOMER]
A14: Telah melaksanakan pengecekan ulang untuk hasil rektifikasi punch list OPM seperti dibawah ini dengan hasil
A15: BAIK dan DITERIMA.
A18: Cluster Name | B18: : | C18: ='support table'!$B$3 -> [NAMA_LOKASI]
A20: Cluster ID | B20: : | C20: ='support table'!$B$4 -> [ID_LOKASI]
A22: ATP Date | B22: :
A26: FDT | B26: No | C26: Defect Item | E26: Defect Description | I26: Punch Point Type | K26: Result | L26: Date of Clearence
B27: 1
B48: ='support table'!$B$9 -> [NAMA_PT_VENDOR] | H48: ='support table'!$B$12 -> [NAMA_PT_CUSTOMER]
B56: Nama | C56: =": " & 'support table'!$B$10 -> : [REP_VENDOR] | J56: Nama | K56: =": " & 'support table'!$B$13 -> : [REP_CUSTOMER]

Sheet BA Splitter FDT
E5: BERITA ACARA SERAH TERIMA SPLITTER
A11: Pada hari___________, Tanggal______________, telah dilaksanakan serah terima Splitter untuk pekerjaan seperti di bawah ini:
B14: Cluster Name | C14: : | D14: ='support table'!$B$3 -> [NAMA_LOKASI]
B15: Cluster ID | C15: : | D15: ='support table'!$B$4 -> [ID_LOKASI]
B16: RFS Date | C16: :
B17: FDT No. | C17: : | D17: ='support table'!$B$7 -> [ID_FDT_FROM]
B19: No. | C19: Item | D19: Quantity | E19: Type | F19: Serial Number | H19: Condition | I19: Remark
B20: 1 | C20: [SPL_ID] | D20: 1 | E20: MODULAR | F20: [SPL_SN] | H20: Good | I20: =C20 -> [SPL_ID]
B21: 2 | C21: [SPL_ID] | D21: 1 | E21: MODULAR | F21: [SPL_SN] | H21: Good | I21: =C21 -> [SPL_ID]
C22: [SPL_ID] | D22: 1 | E22: MODULAR | F22: [SPL_SN] | H22: Good | I22: =C22 -> [SPL_ID]
C23: [SPL_ID] | D23: 1 | E23: MODULAR | F23: [SPL_SN] | H23: Good | I23: =C23 -> [SPL_ID]
C24: [SPL_ID] | D24: 1 | E24: MODULAR | F24: [SPL_SN] | H24: Good | I24: =C24 -> [SPL_ID]
C25: [SPL_ID] | D25: 1 | E25: MODULAR | F25: [SPL_SN] | H25: Good | I25: =C25 -> [SPL_ID]
C26: [SPL_ID] | D26: 1 | E26: MODULAR | F26: [SPL_SN] | H26: Good | I26: =C26 -> [SPL_ID]
C27: [SPL_ID] | D27: 1 | E27: MODULAR | F27: [SPL_SN] | H27: Good | I27: =C27 -> [SPL_ID]
C28: [SPL_ID] | D28: 1 | E28: MODULAR | F28: [SPL_SN] | H28: Good | I28: =C28 -> [SPL_ID]
C29: [SPL_ID] | D29: 1 | E29: MODULAR | F29: [SPL_SN] | H29: Good | I29: =C29 -> [SPL_ID]
B31: HP RFS :
B48: Responsible Vendor | H48: Responsible Customer
B49: Given by, | H49: Received by,
B50: ="Name : " & 'support table'!$B$10 -> Name : [REP_VENDOR] | H50: ="Name: " & 'support table'!$B$13 -> Name: [REP_CUSTOMER]
B51: ID : | H51: ID :
B56: Signature: | H56: Signature:
B57: Date : | H57: Date :

Sheet BA Splitter FAT
E5: BERITA ACARA SERAH TERIMA SPLITTER
A11: Pada hari___________, Tanggal______________, telah dilaksanakan serah terima Splitter untuk pekerjaan seperti di bawah ini:
B14: Cluster Name | C14: : | D14: ='support table'!$B$3 -> [NAMA_LOKASI]
B15: Cluster ID | C15: : | D15: ='support table'!$B$4 -> [ID_LOKASI]
B16: RFS Date | C16: :
B17: FDT No. | C17: : | D17: ='support table'!$B$7 -> [ID_FDT_FROM]
B19: No. | C19: Item | D19: Quantity | E19: Type | F19: Serial Number | H19: Condition | I19: Remark
B20: 1 | C20: Splitter 1 | D20: 1 | E20: MICRO | F20: NO SN | H20: Good | I20: [INPUT_FAT_NAME]
B21: 2 | C21: Splitter 2 | D21: 1 | E21: MICRO | F21: NO SN | H21: Good | I21: [INPUT_FAT_NAME]
B22: 3 | C22: Splitter 3 | D22: 1 | E22: MICRO | F22: NO SN | H22: Good | I22: [INPUT_FAT_NAME]
B23: 4 | C23: Splitter 4 | D23: 1 | E23: MICRO | F23: NO SN | H23: Good | I23: [INPUT_FAT_NAME]
B24: 5 | C24: Splitter 5 | D24: 1 | E24: MICRO | F24: NO SN | H24: Good | I24: [INPUT_FAT_NAME]
B25: 6 | C25: Splitter 6 | D25: 1 | E25: MICRO | F25: NO SN | H25: Good | I25: [INPUT_FAT_NAME]
B26: 7 | C26: Splitter 7 | D26: 1 | E26: MICRO | F26: NO SN | H26: Good | I26: [INPUT_FAT_NAME]
B27: 8 | C27: Splitter 8 | D27: 1 | E27: MICRO | F27: NO SN | H27: Good | I27: [INPUT_FAT_NAME]
B28: 9 | C28: Splitter 9 | D28: 1 | E28: MICRO | F28: NO SN | H28: Good | I28: [INPUT_FAT_NAME]
B29: 10 | C29: Splitter 10 | D29: 1 | E29: MICRO | F29: NO SN | H29: Good | I29: [INPUT_FAT_NAME]
B31: HP RFS :
B48: Responsible Vendor | H48: Responsible Customer
B49: Given by, | H49: Received by,
B50: ="Name : " & 'support table'!$B$10 -> Name : [REP_VENDOR] | H50: ="Name: " & 'support table'!$B$13 -> Name: [REP_CUSTOMER]
B51: ID : | H51: ID :
B56: Signature: | H56: Signature:
B57: Date : | H57: Date :

Sheet BAST Key
A1: BERITA ACARA SERAH TERIMA KUNCI
A6: Pada hari ini, | E6: tanggal | I6: , kami yang bertandatangan di bawah ini :
A11: Nama | C11: =": " & 'support table'!$B$10 -> : [REP_VENDOR]
A12: Perusahaan | C12: =": " & 'support table'!$B$9 -> : [NAMA_PT_VENDOR]
A16: Nama | C16: =": " & 'support table'!$B$13 -> : [REP_CUSTOMER]
A17: Perusahaan | C17: =": " & 'support table'!$B$12 -> : [NAMA_PT_CUSTOMER]
A21: Telah menyerahkan kunci FDT & FAT dari | D21: ='support table'!$B$9 -> [NAMA_PT_VENDOR] | H21: , kepada | I21: ='support table'!$B$12 -> [NAMA_PT_CUSTOMER] | K21: dengan rincian yang tertera pada tabel dibawah ini,
A25: No | B25: Region | C25: OLT | D25: Cluster | J25: FAT | K25: Key | L25: Remaining | N25: FDT | O25: Key | P25: Remaining | R25: Remark
D26: Name | I26: ID | J26: Qty | K26: Qty | N26: Qty | O26: Qty
A27: 1 | B27: ='support table'!$B$2 -> [REGION] | C27: ='support table'!$B$6 -> [NAMA_OLT] | D27: ='support table'!$B$3 -> [NAMA_LOKASI] | I27: ='support table'!$B$4 -> [ID_LOKASI] | K27: =J27*2 -> 0 | O27: =N27 -> 0
B43: Given by: | P43: Received by:
B52: ="Date : " & 'support table'!$B$10 -> Date : [REP_VENDOR] | P52: ="Date : " & 'support table'!$B$13 -> Date : [REP_CUSTOMER]

Sheet BA LAPANGAN
A1: BERITA ACARA LAPANGAN
A7: Proyek | D7: =": " & 'support table'!$B$1 -> : [NAMA_PROYEK]
A8: No PO | C8: :
A9: Nama Cluster | C9: : | D9: ='support table'!$B$3 -> [NAMA_LOKASI]
A10: Pelaksana (Subcontractor) | C10: :
A12: Pada hari ini________________, tanggal /bulan/tahun ____________________________, kami yang bertandatangan di bawah ini:
A14: Pihak Vendor, | H14: Pihak Customer,
A15: Nama | B15: =": " & 'support table'!$B$10 -> : [REP_VENDOR] | H15: Nama | I15: =": " & 'support table'!$B$13 -> : [REP_CUSTOMER]
A16: Jabatan | B16: =": " & 'support table'!$B$11 -> : [JABATAN_VENDOR] | H16: Jabatan | I16: =": " & 'support table'!$B$14 -> : [JABATAN_CUSTOMER]
A19: Menyatakan bahwa:
A44: Pengurus Cluster yang dapat dihubungi:
A45: - | B45: Nama | C45: :
A46: - | B46: Jabatan | C46: :
A47: - | B47: Alamat | C47: :
A48: - | B48: No. Telp | C48: :
C51: , tanggal/bulan/tahun
A55: Dibuat oleh, | C55: Disetujui oleh, | G55: Diketahui oleh, | J55: Diketahui oleh,
A56: PT. Buana Menara Indonesia | C56: Landlord / RT/RW | G56: Vendor | J56: Customer
A63: (...................................) | C63: (...................................) | G63: ="(" & 'support table'!$B$10 -> ([REP_VENDOR] | J63: ="(" & 'support table'!$B$13 -> ([REP_CUSTOMER]
